Workbook

Sheet LEIA_ME
A1: COMPARATIVO DE ORCAMENTOS - ENERGIA SOLAR + CARREGAMENTO DE BYD HIBRIDO
B2: Cliente: Henrique dos Santos Peite | UC Enel SP 0118487990 / 100242856108 | Classe B1 residencial, fornecimento MONOFASICO | Local da instalacao informado: Av. Cel. Sezefredo Fagundes, 8482 C2
B4: 1. OS QUATRO ORCAMENTOS ANALISADOS
B5: A) TecSolarSP - 12 modulos JA Solar 615 W = 7,38 kWp + Huawei 6 kW -> cotacao Belenergy WEB-006506779 = R$ 18.228,70
B6: B) TecSolarSP - 12 modulos Astronergy 605 W = 7,26 kWp + Huawei 6 kW -> cotacao Belenergy WEB-006512519 = R$ 17.307,90
B7: C) SunWash (Yuri) - 10 modulos TCL 620 W = 6,20 kWp + inversor AUXSOL 5 kW -> R$ 14.220,34 INSTALADO
B8: D) SunWash (Yuri) - 10 modulos TCL 620 W = 6,20 kWp + inversor HUAWEI 5 kW -> R$ 15.220,34 INSTALADO
B9: (a SunWash tambem anunciou kits Intelbras de 'ate 500 / 700 / 1000 kWh/mes' por R$ 12.459,81 / 16.190,48 / 20.777,81
B10: + R$ 1.800 de acrescimo regional. Sem quantidade nem potencia de modulo informadas - descartados da comparacao.)
B11: E) William - 10 modulos Maxeon 535 W = 5,35 kWp + Solis 4 kW -> R$ 18.848,91 INSTALADO (kit 11.158,91 + eng. 790 + instal. 6.900)
B12: F) Sun Coast (Alexandre) - 8 modulos RONMA 585 W = 4,68 kWp + AUXSOL 3 kW 1 MPPT -> R$ 12.387,64 INSTALADO
B13: Proposta 40436 de 11/08/2026, valida ate 20/08/2026. CNPJ 47.864.839/0001-31. Unica com garantias declaradas.
B14: G) SunWash (Yuri) - 10 modulos de 650 W = 6,50 kWp + 4 MICROINVERSORES de 2,25 kW -> R$ 16.780,54 INSTALADO
... B82: quantidade real de placas que cabem NAO foram avaliadas nesta analise.

Sheet ENTRADAS
A1: ENTRADAS - DADOS DE PARTIDA
A2: Edite apenas as celulas AMARELAS. Os dados da conta ja sao REAIS (extraidos da fatura). Os dados do BYD ainda sao estimativa.
B4: A) LOCAL E TELHADO
B5: Endereco da unidade consumidora | C5: Av Cel Sezefredo Fagundes 8482 CS 2 | E5: CONFIRMADO na fatura
B6: Bairro / Cidade / CEP | C6: Jardim das Pedras - SAO PAULO/SP - 02367-075 | E6: ALERTA: a peca da TecSolarSP diz 'Franco da Rocha'. A conta diz SAO PAULO capital. Corrigir antes da homologacao
B7: Distribuidora | C7: Enel SP (Eletropaulo Metropolitana) | E7: CONFIRMADO na fatura - CNPJ 61.xxx.xxx/xxxx-93
B8: Orientacao do telhado (azimute) | C8: Sudeste (SE) | E8: Declarado pela TecSolarSP. Penaliza a geracao no hemisferio sul
B9: Inclinacao do telhado | C9: 20 | D9: graus | E9: Declarado pela TecSolarSP
B10: Tipo de telha | C10: A CONFIRMAR | E10: ALERTA: TecSolarSP cotou FIBROCIMENTO e William cotou telha COLONIAL. Um dos dois nao viu o telhado
B11: Sombreamento | C11: NAO AVALIADO | E11: Nao foram enviadas fotos do telhado - area util e sombras nao foram verificadas
B13: B) CONTA DE ENERGIA (TODOS OS VALORES CONFIRMADOS NA FATURA DE JUL/2026)
B14: Classe / subgrupo / modalidade | C14: B1 Residencial Convencional | E14: CONFIRMADO: 'B - B1 - CONVENCIONAL - Residencial'
B15: Numero de fases do padrao ATUAL | C15: 1 | D15: fases | E15: CONFIRMADO na fatura: MONOFASICO (127 V na Enel SP)
B16: Numero de fases DEPOIS do projeto | C16: 2 | D16: fases | E16: ALERTA: todos os inversores cotados sao de 220 V e exigem 2 fases. Este e o valor usado nos calculos
B17: Custo de disponibilidade apos o projeto | C17: =IF(C16=1,30,IF(C16=2,50,100)) -> 50 | D17: kWh/mes | E17: Minimo faturado todo mes. Sobe de 30 para 50 kWh ao virar bifasico - custo permanente
B18: TARIFA EFETIVA TOTAL com tributos | C18: 1.02147 | D18: R$/kWh | E18: CONFIRMADO: R$ 551,59 de energia / 540 kWh. Inclui TUSD + TE + bandeira amarela + PIS/COFINS + ICMS 18%
B19: TUSD com tributos | C19: 0.59643 | D19: R$/kWh | E19: CONFIRMADO na fatura (tarifa sem tributos: R$ 0,46394)
B20: TE - Energia com tributos | C20: 0.40085 | D20: R$/kWh | E20: CONFIRMADO na fatura (tarifa sem tributos: R$ 0,31182)
B21: Adicional de bandeira (amarela em jul/26) | C21: 0.02419 | D21: R$/kWh | E21: CONFIRMADO: R$ 13,06 / 540 kWh. Em bandeira verde este valor e zero
B22: Parcela da TUSD que corresponde ao Fio B | C22: 0.6 | E22: ESTIMATIVA - a fatura nao detalha o Fio B. Pedir a planilha tarifaria da Enel/ANEEL. Faixa usual: 55% a 70% da TUSD
B23: TUSD Fio B com tributos | C23: =C19*C22 -> 0.357858 | D23: R$/kWh | E23: Base de cobranca sobre a energia compensada (Lei 14.300)
B24: % do Fio B faturado em 2026 | C24: 0.6 | E24: Lei 14.300/2022: 60% em 2026, 75% em 2027, 90% em 2028, 100% de 2029 em diante
B25: CUSTO EFETIVO DO FIO B HOJE | C25: =C23*C24 -> 0.2147148 | D25: R$/kWh | E25: E o que voce paga por cada kWh compensado com credito
B26: COSIP / iluminacao publica | C26: 21.11 | D26: R$/mes | E26: CONFIRMADO na fatura. NAO e compensada pela geracao solar
B27: Inflacao energetica anual | C27: 0.07 | D27: %/ano | E27: Premissa. A Enel aplicou +8,8% para residencial em 04/07/2026 (Res. Homologatoria 3.596/26)
B28: Custo da adequacao do padrao (mono -> bifasico) | C28: 2500 | D28: R$ | E28: ESTIMATIVA - nenhum orcamento incluiu. Pedir orcamento de eletricista + taxa Enel. Aplicado a TODAS as opcoes
B30: C) PREMISSAS TECNICAS DO SISTEMA FV
B31: Performance Ratio (PR) | C31: 0.79 | E31: Perdas de ~21%: temperatura, sujeira, cabos, inversor, mismatch
B32: PR do cenario conservador | C32: 0.72 | E32: Usado na linha de sensibilidade do COMPARATIVO. William usou 0,70 na proposta dele
B33: Degradacao no 1o ano | C33: 0.02 | E33: Tipico de modulo novo
B34: Degradacao dos anos seguintes | C34: 0.0045 | D34: %/ano | E34: N-type TOPCon ~0,40%/ano. PERC ~0,55%/ano - o modulo do William e PERC
B35: Manutencao / limpeza (O&M) | C35: 300 | D35: R$/ano | E35: Premissa: 2 limpezas por ano
B36: Provisao anual para troca do inversor | C36: 150 | D36: R$/ano | E36: Inversor dura ~12 a 15 anos, o modulo dura 25+
B37: Autoconsumo instantaneo | C37: 0.3 | E37: Parcela usada no mesmo instante da geracao. Sobe muito se o BYD carregar de dia
B39: D) BYD HIBRIDO >>> DADOS NAO INFORMADOS - TUDO AQUI E ESTIMATIVA <<<
B40: Modelo do veiculo | C40: BYD Song Pro DM-i GL | E40: INFORMADO pelo cliente
B41: Capacidade da bateria | C41: 12.9 | D41: kWh | E41: ESTIMATIVA para o Song Pro DM-i - CONFIRMAR no manual, pois a versao GL pode diferir
B42: Consumo eletrico do veiculo | C42: 16 | D42: kWh/100km | E42: ESTIMATIVA de uso real do Song Pro em modo eletrico. Faixa plausivel: 14 a 18 conforme trajeto e uso de ar-condicionado
B43: Distancia percorrida por dia | C43: 80 | D43: km/dia | E43: INFORMADO pelo cliente
B44: Dias de carregamento por mes | C44: 30 | D44: dias/mes | E44: INFORMADO pelo cliente: carrega todos os dias
...

Sheet CONTA
A1: ANALISE DA CONTA DE ENERGIA - DADOS REAIS DA FATURA
A2: Fonte: fatura Enel SP no 599307231012, ref. 07/2026, UC 0118487990 / 100242856108, NF 085726810 emitida em 30/07/2026.
B4: HISTORICO DE 13 MESES (impresso na fatura) | G4: DECOMPOSICAO DA FATURA DE JUL/2026 (540 kWh)
B5: Mes/Ano | C5: Consumo (kWh) | D5: Dias | E5: Media (kWh/dia) | G5: USO DO SISTEMA DE DISTRIBUICAO (TUSD) | H5: 322.07 | I5: 540 kWh x R$ 0,59643 com tributos (tarifa base R$ 0,46394)
B6: Jul/25 | C6: 389 | D6: 32 | E6: =IFERROR(C6/D6,0) -> 12.15625 | G6: ENERGIA (TE) | H6: 216.46 | I6: 540 kWh x R$ 0,40085 com tributos (tarifa base R$ 0,31182)
B7: Ago/25 | C7: 364 | D7: 31 | E7: =IFERROR(C7/D7,0) -> 11.741935 | G7: ADICIONAL DE BANDEIRA AMARELA | H7: 13.06 | I7: Bandeira aplicada no mes: AMARELA. Em bandeira verde este item e zero
B8: Set/25 | C8: 290 | D8: 29 | E8: =IFERROR(C8/D8,0) -> 10 | G8: Subtotal de faturamento (energia) | H8: 551.59 | I8: Base de calculo do ICMS
B9: Out/25 | C9: 375 | D9: 32 | E9: =IFERROR(C9/D9,0) -> 11.71875 | G9: COSIP - iluminacao publica municipal | H9: 21.11 | I9: Cobrada pela Prefeitura. A geracao solar NAO reduz este item
B10: Nov/25 | C10: 337 | D10: 30 | E10: =IFERROR(C10/D10,0) -> 11.233333 | G10: TOTAL DA FATURA | H10: 572.7 | I10: Vencimento 14/08/2026
B11: Dez/25 | C11: 323 | D11: 29 | E11: =IFERROR(C11/D11,0) -> 11.137931 | G11: TARIFA EFETIVA = 551,59 / 540 | H11: =IFERROR(H8/540,0) -> 1.021463 | I11: R$ 1,0215/kWh. E a tarifa usada em toda a planilha.
B12: Jan/26 | C12: 372 | D12: 32 | E12: =IFERROR(C12/D12,0) -> 11.625
B13: Fev/26 | C13: 348 | D13: 30 | E13: =IFERROR(C13/D13,0) -> 11.6 | G13: TRIBUTOS EMBUTIDOS NA FATURA
B14: Mar/26 | C14: 354 | D14: 29 | E14: =IFERROR(C14/D14,0) -> 12.206897 | G14: PIS/PASEP - base R$ 452,31 a 0,92% | H14: 4.14 | I14: Incide antes do ICMS
B15: Abr/26 | C15: 394 | D15: 32 | E15: =IFERROR(C15/D15,0) -> 12.3125 | G15: COFINS - base R$ 452,31 a 4,23% | H15: 19.12 | I15: Incide antes do ICMS
B16: Mai/26 | C16: 457 | D16: 30 | E16: =IFERROR(C16/D16,0) -> 15.233333 | G16: ICMS - base R$ 551,59 a 18% | H16: 99.28 | I16: Maior tributo da conta
B17: Jun/26 | C17: 422 | D17: 29 | E17: =IFERROR(C17/D17,0) -> 14.551724 | G17: TOTAL DE TRIBUTOS | H17: 122.54 | I17: 21,4% do valor total da fatura
B18: Jul/26 | C18: 540 | D18: 33 | E18: =IFERROR(C18/D18,0) -> 16.363636
B19: Linha 6 = Jul/25 (mes mais antigo). Linha 18 = Jul/26 (mes atual). Verde = menor consumo. Vermelho = maior consumo. | G19: DADOS DA UNIDADE CONSUMIDORA
G20: Distribuidora | H20: Enel SP - Eletropaulo Metropolitana
B21: ESTATISTICAS DOS 12 MESES MAIS RECENTES (Ago/25 a Jul/26) | G21: Unidade consumidora | H21: 0118487990 / 100242856108
B22: TOTAL ANUAL | C22: =SUM(C7:C18) -> 4576 | D22: kWh/ano | G22: Numero do cliente | H22: 24186384
B23: CONSUMO MEDIO MENSAL = soma / 12 | C23: =C22/12 -> 381.33333 | D23: kWh/mes | G23: Classe / subgrupo / modalidade | H23: B - B1 - Convencional - Residencial
B24: Total de dias faturados | C24: =SUM(D7:D18) -> 366 | D24: dias | G24: TIPO DE LIGACAO | H24: MONOFASICO
B25: Consumo medio diario | C25: =IFERROR(C22/C24,0) -> 12.502732 | D25: kWh/dia | G25: Bandeira tarifaria do mes | H25: AMARELA
B26: MAIOR CONSUMO (Jul/26) | C26: =MAX(C7:C18) -> 540 | D26: kWh | G26: Periodo de leitura | H26: 26/06/2026 a 29/07/2026 - 33 dias
B27: MENOR CONSUMO (Set/25) | C27: =MIN(C7:C18) -> 290 | D27: kWh | G27: Proxima leitura prevista | H27: 27/08/2026
B28: Amplitude maior / menor | C28: =IFERROR(C26/C27-1,0) -> 0.86206897 | G28: Medidor | H28: UQM9HDN25C01281527
B29: Consumo do mes atual (Jul/26) | C29: =C18 -> 540 | D29: kWh | G29: Leitura anterior / atual | H29: 3.458 -> 3.998 (constante 1,0)
B30: Mes atual x media dos 12 meses | C30: =IFERROR(C29/C23-1,0) -> 0.41608392 | G30: Reajuste tarifario vigente | H30: +8,8% residencial em 04/07/2026 (Res. Hom. ANEEL 3.596/26)
B31: Media dos 6 meses mais antigos (Ago/25 a Jan/26) | C31: =AVERAGE(C7:C12) -> 343.5 | D31: kWh/mes | G31: Custo de disponibilidade hoje (monofasico) | H31: 30 kWh/mes
B32: Media dos 6 meses mais recentes (Fev/26 a Jul/26) | C32: =AVERAGE(C13:C18) -> 419.16667 | D32: kWh/mes | G32: Custo de disponibilidade se virar bifasico | H32: 50 kWh/mes
B33: TENDENCIA - recentes x antigos | C33: =IFERROR(C32/C31-1,0) -> 0.22028142 | D33: semestre contra semestre | G33: DEC / FEC do conjunto (ano) | H33: DEC 7,46 h / FEC 4,25 interrupcoes
B34: MESMO MES, ANO ANTERIOR: Jul/25 x Jul/26 | C34: =IFERROR(C18/C6-1,0) -> 0.38817481 | D34: compara so julho com julho
B36: TABELA EM ORDEM DE CALENDARIO (usada na aba SIMULACAO_MENSAL)
B37: Mes | C37: Consumo (kWh) | D37: Referencia
B38: Jan | C38: =C12 -> 372 | D38: Jan/26
B39: Fev | C39: =C13 -> 348 | D39: Fev/26
B40: Mar | C40: =C14 -> 354 | D40: Mar/26
B41: Abr | C41: =C15 -> 394 | D41: Abr/26
B42: Mai | C42: =C16 -> 457 | D42: Mai/26
...

Sheet GERACAO
A1: IRRADIACAO E GERACAO POR kWp - REGIAO METROPOLITANA NORTE DE SAO PAULO
A2: HSP estimada para a regiao. CONFIRMAR no CRESESB ou PVGIS com o CEP exato. Fatores de transposicao calculados para latitude -23,3 graus.
B4: Mes | C4: Dias | D4: HSP horizontal (kWh/m2.dia) | E4: Fator SE 20 graus | F4: HSP plano SE | G4: Fator Norte 20 graus | H4: HSP plano Norte | I4: Geracao/kWp SE (kWh/mes) | J4: Geracao/kWp Norte (kWh/mes) | K4: Perda por ser SE
B5: Jan | C5: 31 | D5: 5.3 | E5: 0.97 | F5: =D5*E5 -> 5.141 | G5: 1.02 | H5: =D5*G5 -> 5.406 | I5: =F5*C5*ENTRADAS!$C$31 -> 125.90309 | J5: =H5*C5*ENTRADAS!$C$31 -> 132.39294 | K5: =IFERROR(I5/J5-1,0) -> -0.049019608
B6: Fev | C6: 28 | D6: 5.4 | E6: 0.96 | F6: =D6*E6 -> 5.184 | G6: 1.04 | H6: =D6*G6 -> 5.616 | I6: =F6*C6*ENTRADAS!$C$31 -> 114.67008 | J6: =H6*C6*ENTRADAS!$C$31 -> 124.22592 | K6: =IFERROR(I6/J6-1,0) -> -0.076923077
B7: Mar | C7: 31 | D7: 4.9 | E7: 0.95 | F7: =D7*E7 -> 4.655 | G7: 1.07 | H7: =D7*G7 -> 5.243 | I7: =F7*C7*ENTRADAS!$C$31 -> 114.00095 | J7: =H7*C7*ENTRADAS!$C$31 -> 128.40107 | K7: =IFERROR(I7/J7-1,0) -> -0.11214953
B8: Abr | C8: 30 | D8: 4.4 | E8: 0.94 | F8: =D8*E8 -> 4.136 | G8: 1.11 | H8: =D8*G8 -> 4.884 | I8: =F8*C8*ENTRADAS!$C$31 -> 98.0232 | J8: =H8*C8*ENTRADAS!$C$31 -> 115.7508 | K8: =IFERROR(I8/J8-1,0) -> -0.15315315
B9: Mai | C9: 31 | D9: 3.7 | E9: 0.92 | F9: =D9*E9 -> 3.404 | G9: 1.14 | H9: =D9*G9 -> 4.218 | I9: =F9*C9*ENTRADAS!$C$31 -> 83.36396 | J9: =H9*C9*ENTRADAS!$C$31 -> 103.29882 | K9: =IFERROR(I9/J9-1,0) -> -0.19298246
B10: Jun | C10: 30 | D10: 3.5 | E10: 0.91 | F10: =D10*E10 -> 3.185 | G10: 1.16 | H10: =D10*G10 -> 4.06 | I10: =F10*C10*ENTRADAS!$C$31 -> 75.4845 | J10: =H10*C10*ENTRADAS!$C$31 -> 96.222 | K10: =IFERROR(I10/J10-1,0) -> -0.21551724
B11: Jul | C11: 31 | D11: 3.65 | E11: 0.91 | F11: =D11*E11 -> 3.3215 | G11: 1.15 | H11: =D11*G11 -> 4.1975 | I11: =F11*C11*ENTRADAS!$C$31 -> 81.343535 | J11: =H11*C11*ENTRADAS!$C$31 -> 102.79677 | K11: =IFERROR(I11/J11-1,0) -> -0.20869565
B12: Ago | C12: 31 | D12: 4.55 | E12: 0.93 | F12: =D12*E12 -> 4.2315 | G12: 1.11 | H12: =D12*G12 -> 5.0505 | I12: =F12*C12*ENTRADAS!$C$31 -> 103.62944 | J12: =H12*C12*ENTRADAS!$C$31 -> 123.68675 | K12: =IFERROR(I12/J12-1,0) -> -0.16216216
B13: Set | C13: 30 | D13: 4.45 | E13: 0.95 | F13: =D13*E13 -> 4.2275 | G13: 1.06 | H13: =D13*G13 -> 4.717 | I13: =F13*C13*ENTRADAS!$C$31 -> 100.19175 | J13: =H13*C13*ENTRADAS!$C$31 -> 111.7929 | K13: =IFERROR(I13/J13-1,0) -> -0.10377358
B14: Out | C14: 31 | D14: 4.9 | E14: 0.96 | F14: =D14*E14 -> 4.704 | G14: 1.02 | H14: =D14*G14 -> 4.998 | I14: =F14*C14*ENTRADAS!$C$31 -> 115.20096 | J14: =H14*C14*ENTRADAS!$C$31 -> 122.40102 | K14: =IFERROR(I14/J14-1,0) -> -0.058823529
B15: Nov | C15: 30 | D15: 5.35 | E15: 0.97 | F15: =D15*E15 -> 5.1895 | G15: 1 | H15: =D15*G15 -> 5.35 | I15: =F15*C15*ENTRADAS!$C$31 -> 122.99115 | J15: =H15*C15*ENTRADAS!$C$31 -> 126.795 | K15: =IFERROR(I15/J15-1,0) -> -0.03
B16: Dez | C16: 31 | D16: 5.45 | E16: 0.97 | F16: =D16*E16 -> 5.2865 | G16: 1 | H16: =D16*G16 -> 5.45 | I16: =F16*C16*ENTRADAS!$C$31 -> 129.46639 | J16: =H16*C16*ENTRADAS!$C$31 -> 133.4705 | K16: =IFERROR(I16/J16-1,0) -> -0.03
B17: ANO | C17: =SUM(C5:C16) -> 365 | D17: =AVERAGE(D5:D16) -> 4.6291667 | F17: =AVERAGE(F5:F16) -> 4.3887917 | H17: =AVERAGE(H5:H16) -> 4.9325 | I17: =SUM(I5:I16) -> 1264.269 | J17: =SUM(J5:J16) -> 1421.2345 | K17: =IFERROR(I17/J17-1,0) -> -0.11044307
B18: MEDIA MES | I18: =I17/12 -> 105.35575 | J18: =J17/12 -> 118.43621
B20: A COLUNA I E A CHAVE DE TODA A PLANILHA: quantos kWh cada 1 kWp gera por mes no SEU telhado (Sudeste, 20 graus).
B21: A coluna J mostra o que geraria num telhado Norte. A coluna K e a perda por estar voltado ao Sudeste.
B23: COMPARACAO DIRETA COM O QUE OS VENDEDORES PROMETERAM (celula I17 x J17):
B24: TecSolarSP: 10.554 kWh/ano / 7,38 kWp = 1.430 kWh por kWp. Praticamente identico ao valor NORTE (J17).
B25: Eles declaram o telhado como SUDESTE na propria peca publicitaria. A promessa nao fecha com a orientacao declarada.
B26: SunWash: o anuncio diz textualmente 'CALCULO CONSIDERANDO NORTE DO TELHADO' e vale para Ribeirao Preto ate 80 km.
B27: Ribeirao Preto tem irradiacao maior que Sao Paulo. Sao dois desvios somados a favor do vendedor.
B28: William: usou HSP fixa de 4,5 h/dia e 30% de perdas (PR 0,70), chegando a 1.150 kWh por kWp. E o mais CONSERVADOR
B29: dos tres - abaixo do valor calculado aqui. A proposta dele erra por seguranca, nao por exagero.
B31: CONSEQUENCIA PRATICA DO TELHADO SUDESTE: a geracao se concentra na MANHA e cai a tarde.
B32: Isso favorece carregar o BYD entre 8h e 14h. Desfavorece consumo concentrado no fim da tarde e na noite.
B34: SENSIBILIDADE: com PR de 0,72 (telhado mais sujo, mais quente ou com sombra parcial) a geracao cai cerca de 9%.
B35: A aba COMPARATIVO mostra as duas linhas - realista e conservadora - para voce ver o pior caso.

Sheet BYD
A1: CONSUMO DO BYD HIBRIDO, CARREGADOR E CENARIOS DE CONSUMO
A2: TODOS os dados do veiculo sao ESTIMATIVA - voce ainda nao informou modelo, km/dia nem horario. kW = potencia. kWh = energia.
B4: 1) ENERGIA QUE O CARRO PRECISA (na bateria)
B5: Distancia por dia | C5: =ENTRADAS!C43 -> 80 | D5: km/dia | H5: ESTIMATIVA - o dado que mais muda o resultado
B6: Consumo eletrico do veiculo | C6: =ENTRADAS!C42 -> 16 | D6: kWh/100km | H6: ESTIMATIVA de uso real em modo eletrico
B7: Energia na bateria por dia = MENOR entre o que voce roda e o que voce recarrega | C7: =MIN(C5*C6/100,ENTRADAS!C41*ENTRADAS!C57*ENTRADAS!C58) -> 6.45 | D7: kWh/dia | H7: Roda 80 km = demanda 12,80 kWh/dia. Uma carga de 50% repoe 6,45 kWh/dia. Vale o MENOR: o carro so usa da bateria o que foi reposto
B8: Dias de carregamento por mes | C8: =ENTRADAS!C44 -> 30 | D8: dias/mes | H8: ESTIMATIVA
B9: ENERGIA NECESSARIA PARA O VEICULO POR MES | C9: =C7*C8 -> 193.5 | D9: kWh/mes | H9: Energia UTIL na bateria, ANTES das perdas de carregamento
B11: 2) ENERGIA QUE SAI DA REDE (o que o medidor registra)
B12: Eficiencia de carregamento (tomada -> bateria) | C12: =ENTRADAS!C45 -> 0.86 | H12: 86% adotado: 14% se perde no carregador AC, no BMS e em calor
B13: ENERGIA EFETIVAMENTE CONSUMIDA DA REDE PARA CARREGAR | C13: =C9/C12 -> 225 | D13: kWh/mes | H13: ESTE e o numero que entra na conta de luz e no dimensionamento
B14: Perda de carregamento (energia paga que nao roda) | C14: =C13-C9 -> 31.5 | D14: kWh/mes | H14: Desperdicio inevitavel do processo de carga
B15: Custo do carro na conta de luz SEM solar | C15: =C13*ENTRADAS!C18 -> 229.83075 | D15: R$/mes | H15: Tarifa real de R$ 1,0215/kWh
B16: Custo anual do carro SEM solar | C16: =C15*12 -> 2757.969 | D16: R$/ano
B17: Custo do carro na conta COM solar (so o Fio B) | C17: =C13*ENTRADAS!C25 -> 48.31083 | D17: R$/mes | H17: Compensado por credito: paga-se apenas 60% da TUSD Fio B em 2026
B18: ECONOMIA MENSAL SO NO CARREGAMENTO DO BYD | C18: =C15-C17 -> 181.51992 | D18: R$/mes | H18: Este e o item de maior retorno do projeto
B19: Economia anual so no carregamento do BYD | C19: =C18*12 -> 2178.239 | D19: R$/ano
B20: Custo por km em modo eletrico SEM solar | C20: =IFERROR(C15/(C5*C8),0) -> 0.095762813 | D20: R$/km | H20: Comparar com o custo por km na gasolina
B21: Custo por km em modo eletrico COM solar | C21: =IFERROR(C17/(C5*C8),0) -> 0.020129512 | D21: R$/km | H21: Rodar praticamente de graca
B23: 3) POTENCIA x ENERGIA - CARREGADOR (nao confundir kW com kWh)
B24: Potencia do carregador | C24: =ENTRADAS!C46 -> 3.3 | D24: kW | H24: POTENCIA: define corrente, bitola do cabo e disjuntor
B25: Tempo de carga por dia = energia do dia / potencia | C25: =IFERROR(C13/C8/C24,0) -> 2.2727273 | D25: horas/dia | H25: ENERGIA (kWh) dividida por POTENCIA (kW) = TEMPO (h)
B26: Tempo para carga completa 0-100% | C26: =IFERROR(ENTRADAS!C41/ENTRADAS!C45/C24,0) -> 4.5454545 | D26: horas | H26: Bateria inteira partindo de vazia
B27: Corrente do carregador em 220 V | C27: =IFERROR(C24*1000/220,0) -> 15 | D27: A | H27: Corrente nominal de operacao
B28: Disjuntor do circuito (125% da corrente - NBR 5410) | C28: =IFERROR(C27*1.25,0) -> 18.75 | D28: A | H28: Carga continua: circuito dimensionado a 125%
B29: Energia entregue em 1 hora de carregador ligado | C29: =C24*1 -> 3.3 | D29: kWh | H29: EXEMPLO DA LOGICA: 7,4 kW x 3 h = 22,2 kWh
B31: 4) CENARIOS DE CONSUMO
B32: Cenario | C32: Residencia (kWh/mes) | D32: BYD (kWh/mes) | E32: Margem (kWh/mes) | F32: CONSUMO TOTAL (kWh/mes) | G32: Consumo anual (kWh)
B33: 1 - So a residencia (base pura, sem o carro) | C33: =ENTRADAS!C52 -> 351.82709 | D33: =0 -> 0 | E33: =0 -> 0 | F33: =C33+D33+E33 -> 351.82709 | G33: =F33*12 -> 4221.9251
B34: 2 - RESIDENCIA + BYD tudo no eletrico | C34: =ENTRADAS!C52 -> 351.82709 | D34: =C13 -> 225 | E34: =0 -> 0 | F34: =C34+D34+E34 -> 576.82709 | G34: =F34*12 -> 6921.9251
B35: 3 - RESIDENCIA + BYD + CRESCIMENTO | C35: =ENTRADAS!C52 -> 351.82709 | D35: =C13 -> 225 | E35: =(C35+D35)*ENTRADAS!C48 -> 86.524064 | F35: =C35+D35+E35 -> 663.35116 | G35: =F35*12 -> 7960.2139
C37: ="O BYD aumenta o consumo da residencia em "&TEXT(IFERROR(D34/C34,0),"0.0%")&" - de "&TEXT(C34,"0")&" para "&TEXT(F34,"0")&" kWh/mes." -> O BYD aumenta o consumo da residencia em 64.0% - de 352 para 577 kWh/mes.
C38: ="O Cenario 3 ("&TEXT(F35,"0")&" kWh/mes) e o que deve orientar o dimensionamento, NAO a media de "&TEXT(C33,"0")&" kWh/mes da conta." -> O Cenario 3 (663 kWh/mes) e o que deve orientar o dimensionamento, NAO a media de 352 kWh/mes da conta.
B40: 5) DIA x NOITE - ONDE CARREGAR COMPENSA MAIS
B41: Estrategia | C41: Como funciona | D41: Custo por kWh | E41: Custo mensal do carro | F41: Vantagem | G41: Desvantagem
B42: Carregar de DIA (8h as 14h) | C42: Autoconsumo instantaneo: a energia vai do painel direto para o carro | D42: =0 -> 0 | E42: =0 -> 0 | F42: Nao passa pelo medidor: nao paga Fio B, nao paga nada | G42: Precisa que o carro esteja em casa de manha. Telhado SE gera mais de manha - combina bem
B43: Carregar a NOITE | C43: A geracao do dia vira credito e a noite o credito e usado | D43: =ENTRADAS!C25 -> 0.2147148 | E43: =C13*ENTRADAS!C25 -> 48.31083 | F43: Comodidade: chega, pluga e dorme | G43: Paga o Fio B sobre tudo o que foi compensado. Em 2026 sao 60% da TUSD, em 2029 sera 100%
B44: Carregar SEM energia solar | C44: Tarifa cheia da Enel | D44: =ENTRADAS!C18 -> 1.02147 | E44: =C13*ENTRADAS!C18 -> 229.83075 | F44: Nenhuma | G44: Custo maximo
B45: Ganho anual de carregar de DIA em vez de a NOITE:
C46: =(E43-E42)*12 -> 579.72996 | D46: R$/ano. Parece pouco hoje porque o Fio B esta em 60%. Em 2029 sera 100% e esse ganho quase dobra.
...

Sheet DIMENSIONAMENTO
A1: DIMENSIONAMENTO CORRETO - QUANTO VOCE REALMENTE PRECISA
A2: Calculado a partir do consumo projetado, da irradiacao local, das perdas do sistema e da margem tecnica. Nao por regra de bolo.
B4: A) MEMORIA DE CALCULO
B5: Geracao anual por kWp no seu telhado SE | C5: =GERACAO!I17 -> 1264.269 | D5: kWh por kWp por ano
B6: Geracao mensal por kWp no seu telhado SE | C6: =C5/12 -> 105.35575 | D6: kWh por kWp por mes
B7: Formula usada | C7: ="kWp necessario = consumo anual / "&TEXT(C5,"0")&" kWh por kWp" -> kWp necessario = consumo anual / 1264 kWh por kWp
B9: B) kWp NECESSARIO EM CADA CENARIO
B10: Cenario | C10: Consumo (kWh/mes) | D10: Consumo (kWh/ano) | E10: kWp necessario | F10: Modulos de 615 W
B11: 1 - Atual (so residencia) | C11: =BYD!F33 -> 351.82709 | D11: =C11*12 -> 4221.9251 | E11: =IFERROR(D11/$C$5,0) -> 3.33942 | F11: =IFERROR(ROUNDUP(E11*1000/615,0),0) -> 6
B12: 2 - Residencia + BYD | C12: =BYD!F34 -> 576.82709 | D12: =C12*12 -> 6921.9251 | E12: =IFERROR(D12/$C$5,0) -> 5.4750414 | F12: =IFERROR(ROUNDUP(E12*1000/615,0),0) -> 9
B13: 3 - Residencia + BYD + crescimento | C13: =BYD!F35 -> 663.35116 | D13: =C13*12 -> 7960.2139 | E13: =IFERROR(D13/$C$5,0) -> 6.2962976 | F13: =IFERROR(ROUNDUP(E13*1000/615,0),0) -> 11
B15: C) AS TRES OPCOES DE PROJETO (com modulos de 615 W)
C16: OPCAO A - ECONOMICO | D16: OPCAO B - IDEAL | E16: OPCAO C - COM EXPANSAO
B17: Meta de atendimento | C17: ="100% do Cenario 2" -> 100% do Cenario 2 | D17: ="105% do Cenario 3" -> 105% do Cenario 3 | E17: ="Cenario 3 + folga para dobrar a km do carro" -> Cenario 3 + folga para dobrar a km do carro
B18: kWp alvo | C18: =E12 -> 5.4750414 | D18: =E13*1.05 -> 6.6111125 | E18: =E13*1.25 -> 7.870372
B19: Quantidade de modulos de 615 W | C19: =ROUNDUP(C18*1000/615,0) -> 9 | D19: =ROUNDUP(D18*1000/615,0) -> 11 | E19: =ROUNDUP(E18*1000/615,0) -> 13
B20: Potencia instalada real (kWp) | C20: =C19*615/1000 -> 5.535 | D20: =D19*615/1000 -> 6.765 | E20: =E19*615/1000 -> 7.995
B21: Inversor recomendado (kW) | C21: =5 -> 5 | D21: =6 -> 6 | E21: =7.5 -> 7.5
B22: Relacao DC/AC | C22: =IFERROR(C20/C21,0) -> 1.107 | D22: =IFERROR(D20/D21,0) -> 1.1275 | E22: =IFERROR(E20/E21,0) -> 1.066
B23: Geracao anual estimada (kWh) | C23: =C20*$C$5 -> 6997.7289 | D23: =D20*$C$5 -> 8552.7798 | E23: =E20*$C$5 -> 10107.831
B24: Geracao media mensal (kWh) | C24: =C23/12 -> 583.14407 | D24: =D23/12 -> 712.73165 | E24: =E23/12 -> 842.31922
B25: % do Cenario 2 atendido | C25: =IFERROR(C23/$D$12,0) -> 1.0109513 | D25: =IFERROR(D23/$D$12,0) -> 1.2356071 | E25: =IFERROR(E23/$D$12,0) -> 1.4602629
B26: % do Cenario 3 atendido | C26: =IFERROR(C23/$D$13,0) -> 0.87908805 | D26: =IFERROR(D23/$D$13,0) -> 1.0744409 | E26: =IFERROR(E23/$D$13,0) -> 1.2697938
B27: Excedente anual desperdicado (kWh) | C27: =MAX(0,C23-$D$13) -> 0 | D27: =MAX(0,D23-$D$13) -> 592.56587 | E27: =MAX(0,E23-$D$13) -> 2147.6167
B30: D) RECOMENDACAO DE DIMENSIONAMENTO
B31: A OPCAO B e a recomendada. Motivos tecnicos:
B32: 1. Ela atende o Cenario 3, que e o unico realista: residencia + carro + margem. A Opcao A cobre o carro de hoje mas
B33: nao sobra nada para o crescimento que a propria conta ja mostra (+22% em 6 meses).
B34: 2. Ela nao joga dinheiro fora. Passar do Cenario 3 gera excedente que vira credito e expira em 60 meses - a linha 27
B35: mostra esse desperdicio. Cada kWh gerado acima do consumo tem retorno praticamente zero.
B36: 3. O inversor de 6 kW da Opcao B ainda aceita cerca de 8,1 kWp (limite DC/AC de 1,35), ou seja, permite acrescentar
B37: modulos depois sem trocar o inversor e sem refazer a homologacao. Isso e a expansao futura barata.
B38: 4. A Opcao C so se justifica se voce souber HOJE que a quilometragem do carro vai crescer muito, ou se pretende
B39: instalar ar-condicionado, piscina aquecida ou um segundo veiculo eletrico.
B41: ATENCAO: os numeros acima dependem de km/dia do BYD, que ainda e ESTIMATIVA. Se voce rodar 20 km/dia em vez de 40,
B42: o kWp necessario cai cerca de 1,3 kWp (2 modulos). Se rodar 60 km/dia, sobe cerca de 1,3 kWp. Informe a km real.

Sheet COMPARATIVO
A1: COMPARATIVO DOS ORCAMENTOS - QUADRO PRINCIPAL
A2: Contatos nas linhas 5 a 7. Colunas A e B: TecSolarSP, preco de MATERIAL. As demais: preco INSTALADO. A linha do PRECO TOTAL INSTALADO e a unica comparavel entre todos.
B4: ITEM | C4: A) TecSolarSP JA Solar 615W Huawei 6 kW | D4: B) TecSolarSP Astronergy 605W Huawei 6 kW | E4: C) SunWash TCL 620W AUXSOL 5 kW | F4: D) SunWash TCL 620W HUAWEI 5 kW | G4: E) William Maxeon 535W Solis 4 kW | H4: F) Sun Coast v1 RONMA 585W AUXSOL 3 kW (SUPERADA) | I4: G) SunWash MICRO 10x650W 4x 2,25 kW | J4: H) Sfero (Renato) Longi/DAH 590W 2x micro 2,5 kW | K4: I) Sun Coast v2 TCL 620W x11 AUXSOL 7,5 kW | L4: J) AD BioSolar JA Solar 615W x10 Huawei SUN2000-6KTL-L1 | M4: SIMULACAO G12 MICRO 12x650W 4x Deye 2,25 kW | N4: SIMULACAO G14 MICRO 14x650W 4x Deye 2,25 kW | O4: M) Bruno G4 (a receber) | P4: OBSERVACOES / ALERTAS
B5: EMPRESA / razao social | C5: TecSolarSP | D5: TecSolarSP | E5: SunWash Energia Solar e Ar-Condicionado | F5: SunWash Energia Solar e Ar-Condicionado | G5: nao informada na proposta | H5: Sun Coast Materiais Eletricos e Energia Solar | I5: SunWash Energia Solar e Ar-Condicionado | J5: Sfero | K5: Sun Coast Materiais Eletricos e Energia Solar | L5: AD BioSolar | M5: SunWash - SIMULACAO, preco a confirmar | N5: SunWash - SIMULACAO, preco a confirmar | O5: G4 (razao social a confirmar) | P5: ALERTA: SunWash, William e Sfero nao informaram razao social. Sem empresa identificada nao existe garantia exigivel.
B6: NOME DO RESPONSAVEL | C6: nao informado (razao social: Edijane Gomes dos Santos) | D6: nao informado (razao social: Edijane Gomes dos Santos) | E6: Yuri | F6: Yuri | G6: William | H6: Alexandre | I6: Yuri | J6: nao informado (indicacao do Renato) | K6: Alexandre | L6: Adriano Melo (proposta) / Carlos (negociacao) | M6: Yuri | N6: Yuri | O6: Bruno | P6: Quem falou com voce. Peca sempre que a proposta saia com nome e CNPJ da empresa, nao apenas o contato pessoal.
B7: TELEFONE DE CONTATO | C7: (11) 97365-9192 | D7: (11) 97365-9192 | E7: (16) 99353-4346 | F7: (16) 99353-4346 | G7: (11) 99636-5333 | H7: (11) 91544-8947 | I7: (16) 99353-4346 | J7: (11) 99705-1311 (Renato) | K7: (11) 91544-8947 | L7: (11) 97350-3103 / Carlos (11) 91408-8892 | M7: (16) 99353-4346 | N7: (16) 99353-4346 | O7: (11) 96861-7830 | P7: A Sfero chegou por indicacao do Renato - o telefone e dele, nao da empresa. Pedir o contato direto da Sfero.
B8: CNPJ informado na proposta | C8: 29.775.600/0001-03 | D8: 29.775.600/0001-03 | E8: NAO INFORMADO | F8: NAO INFORMADO | G8: NAO INFORMADO | H8: 47.864.839/0001-31 | I8: NAO INFORMADO | J8: NAO INFORMADO na proposta | K8: 47.864.839/0001-31 | L8: 64.313.573/0001-58 | M8: NAO INFORMADO | N8: NAO INFORMADO | P8: ALERTA: so Sun Coast, AD BioSolar e TecSolarSP (via cotacao do distribuidor) tem CNPJ identificado.
B9: Documento recebido | C9: Cotacao Belenergy WEB-006506779 | D9: Cotacao Belenergy WEB-006512519 | E9: WhatsApp 10/08/2026 | F9: WhatsApp 10/08/2026 | G9: Proposta tecnica de 7 paginas | H9: Proposta 40436 de 11/08/2026 (val. 20/08) | I9: WhatsApp 10/08/2026 17:45 | J9: Proposta 0664/2026 de 11/08/2026 (val. 10 dias) | K9: Proposta 40438 de 11/08/2026 (val. 20/08) | L9: Proposta #01237 de 12/08/2026 (val. 27/08) - substitui a #01225 | M9: SIMULACAO: opcao G escalada para 12 modulos | N9: SIMULACAO: opcao G escalada para 14 modulos | O9: Nada recebido | P9: ALERTA: orcamento por WhatsApp nao e proposta comercial. Sfero, Sun Coast, AD BioSolar e William entregaram documento formal.
B10: TIPO DE PRECO | C10: MATERIAL apenas | D10: MATERIAL apenas | E10: INSTALADO (turnkey) | F10: INSTALADO (turnkey) | G10: INSTALADO (turnkey) | H10: INSTALADO (turnkey) | I10: INSTALADO (turnkey) | J10: INSTALADO (turnkey) | K10: INSTALADO (turnkey) | L10: INSTALADO (turnkey) | M10: INSTALADO (turnkey) | N10: INSTALADO (turnkey) | O10: ? | P10: ALERTA: comparar MATERIAL com INSTALADO e o erro mais comum. As linhas de homologacao e instalacao corrigem isso.
B11: Quantidade de modulos | C11: 12 | D11: 12 | E11: 10 | F11: 10 | G11: 10 | H11: 8 | I11: 10 | J11: 10 | K11: 11 | L11: 10 | M11: 12 | N11: 14 | P11: Informada por cada fornecedor.
B12: Potencia por modulo (W) | C12: 615 | D12: 605 | E12: 620 | F12: 620 | G12: 535 | H12: 585 | I12: 650 | J12: 590 | K12: 620 | L12: 615 | M12: 650 | N12: 650 | P12: A SunWash escreveu '620kw' e '650w' - erro de digitacao para watts.
B13: Fabricante / tecnologia do modulo | C13: JA Solar bifacial N-type | D13: Astronergy bifacial N-type | E13: TCL 620 W (tecnologia a confirmar) | F13: TCL 620 W (tecnologia a confirmar) | G13: Maxeon bifacial PERC | H13: RONMA SOLAR bifacial N-type 144 cel | I13: ZNShine ZXNR-MD132-650 N-type (Tier 1 BNEF) | J13: Longi ou DAH Solar (Tier 1 de verdade) | K13: TCL Solar bifacial N-type 132 cel | L13: JA Solar bifacial N-type 132 cel - TIER 1 | M13: ZNShine ZXNR-MD132-650 N-type (Tier 1 BNEF) | N13: ZNShine ZXNR-MD132-650 N-type (Tier 1 BNEF) | P13: ALERTA: Maxeon do William e PERC, uma geracao atras. TCL e RONMA tem pouquissima rede de assistencia no Brasil. JA Solar, Longi e DAH sao Tier 1 com representacao aqui.
B14: POTENCIA DC (kWp) | C14: =C11*C12/1000 -> 7.38 | D14: =D11*D12/1000 -> 7.26 | E14: =E11*E12/1000 -> 6.2 | F14: =F11*F12/1000 -> 6.2 | G14: =G11*G12/1000 -> 5.35 | H14: =H11*H12/1000 -> 4.68 | I14: =I11*I12/1000 -> 6.5 | J14: =J11*J12/1000 -> 5.9 | ... N14: =N11*N12/1000 -> 9.1 | P14: Quantidade x potencia do modulo / 1000.
B15: Inversor | C15: Huawei 6 kW mono 220V 2 MPPT | D15: Huawei 6 kW mono 220V 2 MPPT | E15: AUXSOL 5 kW (modelo nao informado) | F15: HUAWEI 5 kW (modelo nao informado) | G15: Solis 4 kW mono 220V 2 MPPT | H15: AUXSOL 3 kW mono 220V 1 MPPT | I15: 4x DEYE SUN-S225G4-EU-Q0 2,25 kW = 9,0 kW AC | J15: 2x microinversor 2,5 kW = 5,0 kW AC - Solis ou Growatt | K15: AUXSOL 7,5 kW mono 220V 2 MPPT (100% over) | L15: HUAWEI SUN2000-6KTL-L1 6.000 W (modelo EXATO informado) | M15: 4x DEYE SUN-S225G4-EU-Q0 = 9,0 kW AC (12 dos 16 canais) | N15: 4x DEYE SUN-S225G4-EU-Q0 = 9,0 kW AC (14 dos 16 canais) | P15: ALERTA: AUXSOL tem baixa penetracao no Brasil. Huawei, Solis e Growatt tem assistencia estabelecida. So a AD BioSolar informou o MODELO EXATO.
B16: Potencia AC do inversor (kW) | C16: 6 | D16: 6 | E16: 5 | F16: 5 | G16: 4 | H16: 3 | I16: 9 | J16: 5 | K16: 7.5 | L16: 6 | M16: 9 | N16: 9 | P16: Exigir o codigo exato do modelo, como fez a AD BioSolar (SUN2000-5KTL-L1).
B17: Numero de MPPTs | C17: 2 | D17: 2 | E17: a confirmar | F17: a confirmar | G17: 2 | H17: 1 | I17: 4 por micro = 16 canais (10 usados, 6 livres) | J17: 1 por modulo (10 MPPTs) | K17: 2 | L17: 2 (a confirmar) | M17: 4 por micro = 16 canais (12 usados, 4 livres) | N17: 4 por micro = 16 canais (14 usados, 2 livres) | P17: ALERTA: Sun Coast v1 usava 1 MPPT UNICO para 8 modulos. As opcoes com microinversor dao 1 MPPT POR MODULO: sombra em um modulo nao afeta os outros e permite usar mais de uma agua do telhado.
B18: RELACAO DC/AC | C18: =IFERROR(C14/C16,0) -> 1.23 | D18: =IFERROR(D14/D16,0) -> 1.21 | E18: =IFERROR(E14/E16,0) -> 1.24 | F18: =IFERROR(F14/F16,0) -> 1.24 | G18: =IFERROR(G14/G16,0) -> 1.3375 | H18: =IFERROR(H14/H16,0) -> 1.56 | I18: =IFERROR(I14/I16,0) -> 0.72222222 | J18: =IFERROR(J14/J16,0) -> 1.18 | ... N18: =IFERROR(N14/N16,0) -> 1.0111111 | P18: ALERTA: faixa saudavel de 1,10 a 1,35. Sun Coast v1 em 1,56 = clipping e risco de perder garantia. Abaixo de 1,10 voce pagou por inversor que nao vai usar - aceitavel se for folga proposital para expansao.
B19: Tensao de operacao | C19: 220 V (2 fases) | D19: 220 V (2 fases) | E19: 220 V (a confirmar) | F19: 220 V (a confirmar) | G19: 220 V (2 fases) | H19: 220 V (2 fases) | I19: 220 V (a confirmar) | J19: 220 V (a confirmar) | K19: 220 V (2 fases) | L19: 220 V (2 fases) | M19: 220 V (a confirmar) | N19: 220 V (a confirmar) | P19: ALERTA MAIOR: sua ligacao e MONOFASICA (127 V na Enel SP). TODOS exigem mudanca para bifasico.
B20: Tipo de telha que o orcamento considerou | C20: Fibrocimento | D20: Fibrocimento | E20: nao informada | F20: nao informada | G20: Colonial | H20: Colonial | I20: nao informada | J20: Ceramico / colonial | K20: Colonial | L20: nao informada | M20: nao informada | N20: nao informada | P20: ALERTA: William, Sun Coast e Sfero dizem CERAMICA/COLONIAL; a TecSolarSP diz FIBROCIMENTO. Tres contra um. Se for ceramica, a estrutura das duas cotacoes da TecSolarSP esta errada. Uma foto resolve.
B21: Area de telhado necessaria (m2) | C21: =C11*C12*0.00452 -> 33.3576 | D21: =D11*D12*0.00452 -> 32.8152 | E21: =E11*E12*0.00452 -> 28.024 | F21: =F11*F12*0.00452 -> 28.024 | G21: =G11*G12*0.00452 -> 24.182 | H21: 21.12 | I21: =I11*I12*0.00452 -> 29.38 | J21: 28 | K21: 30.58 | L21: 32.41 | M21: =M11*M12*0.00452 -> 35.256 | N21: =N11*N12*0.00452 -> 41.132 | P21: Valores em azul foram DECLARADOS pelo fornecedor; os demais estimados a 0,00452 m2 por watt. Sem fotos do telhado NAO foi verificado se essa area existe na agua Sudeste.
B22: Garantia declarada do modulo | C22: nao informada | D22: nao informada | E22: nao informada | F22: nao informada | G22: nao informada | H22: 25 anos eficiencia / 15 anos defeito | I22: nao declarada pelo vendedor - exigir por escrito (N-type costuma dar 12/25 a 30 anos) | J22: 12 anos produto / 25 anos eficiencia | K22: 25 anos eficiencia / 15 anos defeito | L22: 15 anos defeito / 30 anos eficiencia | M22: exigir por escrito | N22: exigir por escrito | P22: AD BioSolar tem a melhor: 30 anos de eficiencia e 15 de defeito. TecSolarSP, SunWash e William nao declararam nada.
B23: Garantia declarada do inversor | C23: nao informada | D23: nao informada | E23: nao informada | F23: nao informada | G23: nao informada | H23: 10 a 25 anos | I23: nao declarada pelo vendedor - a Deye pratica 10 anos, exigir por escrito | J23: 7 a 10 anos | K23: 10 a 25 anos | L23: 10 anos | M23: exigir por escrito (Deye pratica 10 anos) | N23: exigir por escrito (Deye pratica 10 anos) | P23: AD BioSolar declara 10 anos para um modelo Huawei nomeado - e a unica verificavel. '10 a 25 anos' da Sun Coast e vago.
B24: Garantia de servico / seguro | C24: nao informada | D24: nao informada | E24: nao informada | F24: nao informada | G24: nao informada | H24: 12 meses | I24: nao informada | J24: 1 ano instalacao + SEGURO ALL RISK 1 ano + GARANTIA DE PERFORMANCE EM CONTRATO | K24: 12 meses | L24: vistoria tecnica, ART, licencas, gestao de obra e frete inclusos | M24: exigir por escrito | N24: exigir por escrito | P24: So a Sfero oferece seguro All Risk e garantia de performance em contrato. Isso vale dinheiro em risco.
B25: Exclusoes declaradas na proposta | C25: nao informadas | D25: nao informadas | E25: nao informadas | F25: nao informadas | G25: nao informadas | H25: padrao de entrada, obras civis, telhado, eletrodutos, ART estrutural | I25: nao informadas | J25: obras civis, reformas no telhado/laje e no PADRAO DE ENTRADA | K25: padrao de entrada, obras civis, telhado, eletrodutos, ART estrutural | L25: alvenaria, reforco estrutural e alteracoes na rede pedidas pela concessionaria | M25: exigir por escrito | N25: exigir por escrito | P25: ALERTA: Sun Coast, Sfero e AD BioSolar excluem por escrito a adequacao do padrao. E honesto declarar, mas o custo e seu. Quem nao declarou exclusao tambem nao incluiu - so nao avisou.
B26: Condicao de pagamento declarada | C26: PIX (cotacao de material) | D26: PIX (cotacao de material) | E26: a vista ou 21x COM juros | F26: a vista ou 21x COM juros | G26: PIX no kit; restante nao informado | H26: a vista, cartao 12x/21x COM juros ou financiamento 36x | I26: 18x de R$ 932,25 SEM JUROS (= preco a vista) | J26: 3x: 60% entrada / 20% montado / 20% ligado; ou Santander 60x R$ 553 ou 72x R$ 507 | K26: a vista, cartao 12x/21x COM juros ou financiamento 36x ate 120x | L26: R$ 16.200 NEGOCIADO (o PDF traz R$ 21.289 - EXIGIR O DESCONTO POR ESCRITO) | M26: pedir preco e parcelamento para esta configuracao | N26: pedir preco e parcelamento para esta configuracao | P26: ATENCAO: 18x SEM JUROS pelo valor a vista (SunWash micro) e vantagem real. Ja o financiamento Sfero em 72x custa cerca de R$ 17,8 mil de juros sobre R$ 18,7 mil - quase dobra o preco.
B28: PRECOS
B29: Preco BASE informado (R$) | C29: 18228.7 | D29: 17307.9 | E29: 14220.34 | F29: 15220.34 | G29: 11158.91 | H29: 12387.64 | I29: 16780.54 | J29: 18733 | K29: 16890 | L29: 16200 | M29: =I29+2*ENTRADAS!$C$54 -> 18580.54 | N29: =I29+4*ENTRADAS!$C$54 -> 20380.54 | P29: A, B e E: valor do KIT/material. As demais: projeto completo, ja com instalacao. ALERTA na coluna J: o PDF da AD BioSolar traz R$ 21.289,00 e o valor de R$ 16.200,00 foi negociado verbalmente - um desconto de R$ 5.089 (24%) que PRECISA constar em proposta assinada, senao pode evaporar na hora de fechar.
B30: Acrescimo regional a confirmar (R$) | C30: 0 | D30: 0 | E30: 1800 | F30: 1800 | G30: 0 | H30: 0 | I30: 1800 | J30: 0 | K30: 0 | L30: 0 | M30: 1800 | N30: 1800 | P30: ALERTA: a SunWash citou +R$ 1.800 pela sua regiao no kit Intelbras e nao repetiu nos demais. Mantido por PRUDENCIA. Se nao incidir, zere e o payback melhora.
B31: Homologacao / engenharia / ART (R$) | C31: 790 | D31: 790 | E31: 0 | F31: 0 | G31: 790 | H31: 0 | I31: 0 | J31: 0 | K31: 0 | L31: 0 | M31: 0 | N31: 0 | P31: E: R$ 790 declarado pelo William. A e B: mesmo valor como ESTIMATIVA - a TecSolarSP nunca informou o preco de venda.
B32: Instalacao / mao de obra (R$) | C32: =6900/10*C11 -> 8280 | D32: =6900/10*D11 -> 8280 | E32: 0 | F32: 0 | G32: 6900 | H32: 0 | I32: 0 | J32: 0 | K32: 0 | L32: 0 | M32: 0 | N32: 0 | P32: ALERTA: E = R$ 6.900 declarado pelo William para 10 modulos. A e B usam esse valor escalado por modulo, como ESTIMATIVA.
B33: Adequacao do padrao mono -> bifasico (R$) | C33: =ENTRADAS!$C$28 -> 2500 | D33: =ENTRADAS!$C$28 -> 2500 | E33: =ENTRADAS!$C$28 -> 2500 | F33: =ENTRADAS!$C$28 -> 2500 | G33: =ENTRADAS!$C$28 -> 2500 | H33: =ENTRADAS!$C$28 -> 2500 | I33: =ENTRADAS!$C$28 -> 2500 | J33: =ENTRADAS!$C$28 -> 2500 | ... N33: =ENTRADAS!$C$28 -> 2500 | P33: ALERTA: NENHUM dos orcamentos incluiu. Necessario para qualquer inversor de 220 V. Editavel em ENTRADAS!C28.
B34: PRECO TOTAL INSTALADO (R$) | C34: =SUM(C29:C33) -> 29798.7 | D34: =SUM(D29:D33) -> 28877.9 | E34: =SUM(E29:E33) -> 18520.34 | F34: =SUM(F29:F33) -> 19520.34 | G34: =SUM(G29:G33) -> 21348.91 | H34: =SUM(H29:H33) -> 14887.64 | I34: =SUM(I29:I33) -> 21080.54 | J34: =SUM(J29:J33) -> 21233 | ... N34: =SUM(N29:N33) -> 24680.54 | P34: O UNICO numero comparavel entre fornecedores.
B35: R$ por Wp instalado | C35: =IFERROR(C34/(C14*1000),0) -> 4.0377642 | D35: =IFERROR(D34/(D14*1000),0) -> 3.9776722 | E35: =IFERROR(E34/(E14*1000),0) -> 2.9871516 | F35: =IFERROR(F34/(F14*1000),0) -> 3.1484419 | G35: =IFERROR(G34/(G14*1000),0) -> 3.9904505 | H35: =IFERROR(H34/(H14*1000),0) -> 3.1811197 | I35: =IFERROR(I34/(I14*1000),0) -> 3.24316 | J35: =IFERROR(J34/(J14*1000),0) -> 3.5988136 | ... N35: =IFERROR(N34/(N14*1000),0) -> 2.7121473 | P35: Metrica de mercado, valida so entre precos de mesmo escopo.
B36: R$ por Wp somente de material | C36: =IFERROR(C29/(C14*1000),0) -> 2.4700136 | D36: =IFERROR(D29/(D14*1000),0) -> 2.3840083 | E36: n/d | F36: n/d | G36: =IFERROR(G29/(G14*1000),0) -> 2.0857776 | H36: n/d | I36: n/d | J36: n/d | K36: n/d | L36: n/d | M36: n/d | N36: n/d | P36: Mede a margem. A TecSolarSP paga R$ 2,47/Wp de material: use isso para negociar o preco de venda dela.
B38: GERACAO - REALIDADE x PROMESSA
B39: Geracao anual realista - telhado SE (kWh) | C39: =C14*GERACAO!$I$17 -> 9330.3052 | D39: =D14*GERACAO!$I$17 -> 9178.5929 | E39: =E14*GERACAO!$I$17 -> 7838.4678 | F39: =F14*GERACAO!$I$17 -> 7838.4678 | G39: =G14*GERACAO!$I$17 -> 6763.8391 | H39: =H14*GERACAO!$I$17 -> 5916.7789 | I39: =I14*GERACAO!$I$17 -> 8217.7485 | J39: =J14*GERACAO!$I$17 -> 7459.1871 | ... N39: =N14*GERACAO!$I$17 -> 11504.848 | P39: Irradiacao de Sao Paulo, telhado Sudeste 20 graus, PR de 79%.
B40: Geracao media mensal realista (kWh/mes) | C40: =C39/12 -> 777.52543 | D40: =D39/12 -> 764.88274 | E40: =E39/12 -> 653.20565 | F40: =F39/12 -> 653.20565 | G40: =G39/12 -> 563.65326 | H40: =H39/12 -> 493.06491 | I40: =I39/12 -> 684.81237 | J40: =J39/12 -> 621.59892 | ... N40: =N39/12 -> 958.73732
B41: Geracao no cenario CONSERVADOR (PR 72%) | C41: =C39/ENTRADAS!$C$31*ENTRADAS!$C$32 -> 8503.5693 | D41: =D39/ENTRADAS!$C$31*ENTRADAS!$C$32 -> 8365.2999 | E41: =E39/ENTRADAS!$C$31*ENTRADAS!$C$32 -> 7143.92 | F41: =F39/ENTRADAS!$C$31*ENTRADAS!$C$32 -> 7143.92 | G41: =G39/ENTRADAS!$C$31*ENTRADAS!$C$32 -> 6164.5116 | H41: =H39/ENTRADAS!$C$31*ENTRADAS!$C$32 -> 5392.5073 | I41: =I39/ENTRADAS!$C$31*ENTRADAS!$C$32 -> 7489.5935 | J41: =J39/ENTRADAS!$C$31*ENTRADAS!$C$32 -> 6798.2464 | ... N41: =N39/ENTRADAS!$C$31*ENTRADAS!$C$32 -> 10485.431 | P41: Pior caso: telhado mais sujo, mais quente ou com sombra parcial.
B42: Geracao PROMETIDA pelo vendedor (kWh/ano) | C42: 10554 | D42: 0 | E42: 8400 | F42: 8400 | G42: 6151 | H42: 6367.5 | I42: 8400 | J42: 7329.96 | K42: 9279.13 | L42: 7981.26 | M42: 0 | N42: 0 | P42: A: 10.554. C, D e G: 700 kWh/mes x 12. E: 6.151. F: 6.367,50. H: 7.329,96. I: 9.279,13. J: 7.981,26. B: nao informada.
B43: DESVIO DA PROMESSA | C43: =IFERROR(C39/C42-1,0) -> -0.11594607 | D43: =IFERROR(D39/D42-1,0) -> 0 | E43: =IFERROR(E39/E42-1,0) -> -0.066849075 | F43: =IFERROR(F39/F42-1,0) -> -0.066849075 | G43: =IFERROR(G39/G42-1,0) -> 0.099632438 | H43: =IFERROR(H39/H42-1,0) -> -0.070784626 | I43: =IFERROR(I39/I42-1,0) -> -0.021696611 | J43: =IFERROR(J39/J42-1,0) -> 0.017629983 | ... N43: =IFERROR(N39/N42-1,0) -> 0 | P43: ALERTA: negativo = o vendedor promete mais do que o telhado entrega. Positivo = foi conservador. Sfero e a unica positiva.
...

Sheet BOM_DETALHADO
A1: LISTA DE MATERIAIS - AS TRES COTACOES BELENERGY LADO A LADO
A2: Os tres orcamentos vem do MESMO distribuidor (Belenus/BelEnergy). Isso permite comparar escopo item por item.
B4: ITEM | C4: A) TecSolarSP JA Solar 615W WEB-006506779 | D4: B) TecSolarSP Astronergy 605W WEB-006512519 | E4: E) William Maxeon 535W WEB-006493952 | F4: ANALISE TECNICA
B5: Modulo fotovoltaico | C5: 12 pc JA Solar 615 W bifacial N-type | D5: 12 pc Astronergy 605 W bifacial N-type | E5: 10 pc Maxeon 535 W bifacial PERC | F5: A e B usam N-type TOPCon (geracao atual). E usa PERC, tecnologia anterior: menor eficiencia por m2 e degradacao maior.
B6: Inversor | C6: Huawei 6 kW mono 220 V 2 MPPT | D6: Huawei 6 kW mono 220 V 2 MPPT | E6: Solis 4 kW mono 220 V 2 MPPT | F6: TODOS de 220 V - incompativeis com o padrao monofasico atual sem adequacao. O Solis de 4 kW limita a expansao futura a zero.
B7: Estrutura - suporte de telhado | C7: 18 pc suporte pe em L FIBROCIMENTO | D7: 18 pc suporte pe em L FIBROCIMENTO | E7: 10 pc gancho telha COLONIAL c/ prolongador | F7: CONTRADICAO GRAVE: TecSolarSP cotou FIBROCIMENTO; William e Sun Coast cotaram TELHA COLONIAL. Dois contra um. Se for colonial, a estrutura das duas cotacoes da TecSolarSP esta errada. Resolver com uma foto antes de comprar.
B8: Haste / fixacao | C8: 18 pc haste 10x250 mm inox (madeira) | D8: 20 pc haste 10x250 mm inox | E8: incluso no gancho | F8: Fixacao por perfuracao exige vedacao com arruela EPDM. Exigir garantia contra infiltracao.
B9: Perfil de fixacao | C9: 24 pc de 2,70 m | D9: 24 pc de 2,70 m | E9: 10 pc de 2,28 m | F9: Compativel com a quantidade de modulos de cada projeto.
B10: Grampos final / intermediario | C10: 6 jg final + 6 jg intermediario | D10: 6 jg final + 6 jg intermediario | E10: 2 jg final + 10 jg intermediario | F10: Sem observacao relevante.
B11: Garra de aterramento | C11: 6 jg | D11: 3 jg | E11: 2 jg | F11: ALERTA: quantidade cai muito em B e E. Aterramento de moldura e estrutura precisa ser continuo em todas as fileiras.
B12: Cabo solar CC | C12: 30 m vermelho + 30 m preto de 6 mm2 | D12: 30 m vermelho + 30 m preto de 4 mm2 | E12: 25 m vermelho + 25 m preto de 4 mm2 | F12: Bitola de 4 mm2 atende em corrente, mas verificar queda de tensao no percurso real telhado-inversor.
B13: Cabo de aterramento / equipotencializacao | C13: 20 m de 4 mm2 verde | D13: NAO INCLUIDO | E13: 10 m de 6 mm2 verde | F13: ALERTA: a cotacao B nao tem condutor de equipotencializacao. Item de seguranca, nao e opcional.
B14: String box CC | C14: 1 pc 2E/2S 1000 V Clamper | D14: 1 pc 2E/2S 1000 V Clamper | E14: 1 pc 2-4E/2-4S 1000 V | F14: Verificar em todas se contem DPS CC e chave seccionadora sob carga.
B15: DPS do lado CA | C15: NAO INCLUIDO | D15: NAO INCLUIDO | E15: 3 pc Clamper classe II 275 V 15 kA | F15: ALERTA: so o William incluiu protecao contra surto no lado CA. Nas duas da TecSolarSP falta - e obrigatorio pela NBR 5410.
... B20: Garantia do distribuidor | C20: 1 ano Belenus | D20: 1 ano Belenus | E20: 1 ano Belenus | F20: A Belenus cobre 1 ano. Todo o resto (25 a 30 anos do modulo, 5 a 10 do inversor) e garantia do FABRICANTE, nao do integrador.
B22: FECHAMENTO FINANCEIRO DAS COTACOES DE MATERIAL
B23: Componente | C23: A) JA Solar 615W | D23: B) Astronergy 605W | E23: E) William Maxeon 535W
B24: Total de produtos | C24: 17344.82 | D24: 16588.37 | E24: 10565.21
B25: Frete | C25: 732.44 | D25: 719.53 | E25: 593.7
B26: Seguro | C26: 151.44 | D26: 0 | E26: 0
B27: ICMS / IPI / ST / DIFAL | C27: 0 | D27: 0 | E27: 0
B28: TOTAL DO KIT (material) | C28: =SUM(C24:C27) -> 18228.7 | D28: =SUM(D24:D27) -> 17307.9 | E28: =SUM(E24:E27) -> 11158.91
B30: Potencia do sistema (kWp) | C30: =COMPARATIVO!C14 -> 7.38 | D30: =COMPARATIVO!D14 -> 7.26 | E30: =COMPARATIVO!G14 -> 5.35
B31: Custo do material por Wp | C31: =IFERROR(C28/(C30*1000),0) -> 2.4700136 | D31: =IFERROR(D28/(D30*1000),0) -> 2.3840083 | E31: =IFERROR(E28/(E30*1000),0) -> 2.0857776
B33: Mao de obra + engenharia declarada pelo William | C33: R$ 7.690,00 para 10 modulos = R$ 769 por modulo, ou R$ 1,44 por Wp
B34: Margem que o William cobrou sobre o kit | C34: =IFERROR(7690/E28,0) -> 0.68913541 | D34: Referencia de mercado para negociar com a TecSolarSP: eles pagam R$ 18.228,70 de material.
B35: Preco de venda justo estimado para a opcao A | C35: =C28+790+6900/10*12 -> 27298.7 | D35: Se a TecSolarSP pedir muito acima disso, ha espaco para negociar - agora voce sabe o custo deles.
B37: A opcao A (615 W) vale os R$ 920,80 a mais que a opcao B (605 W)?
B38: Diferenca de preco do material | C38: =C28-D28 -> 920.8
B39: Geracao anual extra da opcao A (kWh) | C39: =COMPARATIVO!C39-COMPARATIVO!D39 -> 151.71228
B40: Valor dessa geracao extra por ano | C40: =C39*ENTRADAS!C18 -> 154.96954
B41: Anos para a geracao extra pagar a diferenca | C41: =IFERROR(C38/C40,0) -> 5.9418127 | D41: Se der acima de ~6 anos, a diferenca NAO se paga pela geracao: decida por marca, garantia e completude do kit (a opcao A tem aterramento completo, a B nao).

Sheet ECONOMIA
A1: MODELO DE ECONOMIA - ANO 1, PELAS REGRAS DA LEI 14.300/2022
A2: Base: Cenario 3 (residencia + BYD + margem). A conta NAO vai a zero: permanecem custo de disponibilidade, Fio B e COSIP.
B4: LINHA DE CALCULO | C4: A) TecSolarSP JA Solar 615W Huawei 6 kW | D4: B) TecSolarSP Astronergy 605W Huawei 6 kW | E4: C) SunWash TCL 620W AUXSOL 5 kW | F4: D) SunWash TCL 620W HUAWEI 5 kW | G4: E) William Maxeon 535W Solis 4 kW | H4: F) Sun Coast v1 RONMA 585W AUXSOL 3 kW (SUPERADA) | I4: G) SunWash MICRO 10x650W 4x 2,25 kW | J4: H) Sfero (Renato) Longi/DAH 590W 2x micro 2,5 kW | K4: I) Sun Coast v2 TCL 620W x11 AUXSOL 7,5 kW | L4: J) AD BioSolar JA Solar 615W x10 Huawei SUN2000-6KTL-L1 | M4: SIMULACAO G12 MICRO 12x650W 4x Deye 2,25 kW | N4: SIMULACAO G14 MICRO 14x650W 4x Deye 2,25 kW | O4: M) Bruno G4 (a receber) | P4: EXPLICACAO
B5: Consumo anual - Cenario 3 (kWh) | C5: =BYD!$G$35 -> 7960.2139 | D5: =BYD!$G$35 -> 7960.2139 | E5: =BYD!$G$35 -> 7960.2139 | F5: =BYD!$G$35 -> 7960.2139 | G5: =BYD!$G$35 -> 7960.2139 | H5: =BYD!$G$35 -> 7960.2139 | I5: =BYD!$G$35 -> 7960.2139 | J5: =BYD!$G$35 -> 7960.2139 | ... N5: =BYD!$G$35 -> 7960.2139 | P5: Residencia + BYD + margem de crescimento
B6: Geracao anual do sistema (kWh) | C6: =COMPARATIVO!C39 -> 9330.3052 | D6: =COMPARATIVO!D39 -> 9178.5929 | E6: =COMPARATIVO!E39 -> 7838.4678 | F6: =COMPARATIVO!F39 -> 7838.4678 | G6: =COMPARATIVO!G39 -> 6763.8391 | H6: =COMPARATIVO!H39 -> 5916.7789 | I6: =COMPARATIVO!I39 -> 8217.7485 | J6: =COMPARATIVO!J39 -> 7459.1871 | ... N6: =COMPARATIVO!N39 -> 11504.848 | P6: Geracao realista no telhado Sudeste
B7: Tarifa efetiva (R$/kWh) | C7: =ENTRADAS!$C$18 -> 1.02147 | D7: =ENTRADAS!$C$18 -> 1.02147 | E7: =ENTRADAS!$C$18 -> 1.02147 | F7: =ENTRADAS!$C$18 -> 1.02147 | G7: =ENTRADAS!$C$18 -> 1.02147 | H7: =ENTRADAS!$C$18 -> 1.02147 | I7: =ENTRADAS!$C$18 -> 1.02147 | J7: =ENTRADAS!$C$18 -> 1.02147 | ... N7: =ENTRADAS!$C$18 -> 1.02147 | P7: R$ 1,0215 - calculado da fatura real de jul/2026
B8: CONTA ANUAL SEM SOLAR, COM O BYD (R$) | C8: =C5*C7+ENTRADAS!$C$26*12 -> 8384.4397 | D8: =D5*D7+ENTRADAS!$C$26*12 -> 8384.4397 | E8: =E5*E7+ENTRADAS!$C$26*12 -> 8384.4397 | F8: =F5*F7+ENTRADAS!$C$26*12 -> 8384.4397 | G8: =G5*G7+ENTRADAS!$C$26*12 -> 8384.4397 | H8: =H5*H7+ENTRADAS!$C$26*12 -> 8384.4397 | I8: =I5*I7+ENTRADAS!$C$26*12 -> 8384.4397 | J8: =J5*J7+ENTRADAS!$C$26*12 -> 8384.4397 | ... N8: =N5*N7+ENTRADAS!$C$26*12 -> 8384.4397 | P8: O cenario que voce enfrenta se nao instalar nada e o carro chegar
B9: Autoconsumo instantaneo (kWh) | C9: =MIN(C5,C6)*ENTRADAS!$C$37 -> 2388.0642 | D9: =MIN(D5,D6)*ENTRADAS!$C$37 -> 2388.0642 | E9: =MIN(E5,E6)*ENTRADAS!$C$37 -> 2351.5403 | F9: =MIN(F5,F6)*ENTRADAS!$C$37 -> 2351.5403 | G9: =MIN(G5,G6)*ENTRADAS!$C$37 -> 2029.1517 | H9: =MIN(H5,H6)*ENTRADAS!$C$37 -> 1775.0337 | I9: =MIN(I5,I6)*ENTRADAS!$C$37 -> 2388.0642 | J9: =MIN(J5,J6)*ENTRADAS!$C$37 -> 2237.7561 | ... N9: =MIN(N5,N6)*ENTRADAS!$C$37 -> 2388.0642 | P9: Usado no instante da geracao: nao passa pelo medidor, nao paga nada
B10: Energia injetada na rede (kWh) | C10: =C6-C9 -> 6942.241 | D10: =D6-D9 -> 6790.5287 | E10: =E6-E9 -> 5486.9274 | F10: =F6-F9 -> 5486.9274 | G10: =G6-G9 -> 4734.6874 | H10: =H6-H9 -> 4141.7452 | I10: =I6-I9 -> 5829.6843 | J10: =J6-J9 -> 5221.4309 | ... N10: =N6-N9 -> 9116.7837 | P10: Vira credito de energia
B11: Consumo minimo faturavel - disponibilidade (kWh) | C11: =ENTRADAS!$C$17*12 -> 600 | D11: =ENTRADAS!$C$17*12 -> 600 | E11: =ENTRADAS!$C$17*12 -> 600 | F11: =ENTRADAS!$C$17*12 -> 600 | G11: =ENTRADAS!$C$17*12 -> 600 | H11: =ENTRADAS!$C$17*12 -> 600 | I11: =ENTRADAS!$C$17*12 -> 600 | J11: =ENTRADAS!$C$17*12 -> 600 | ... N11: =ENTRADAS!$C$17*12 -> 600 | P11: 50 kWh/mes apos virar bifasico. Nunca compensavel
B12: Energia compensada com creditos (kWh) | C12: =MAX(0,MIN(C10,C5-C9-C11)) -> 4972.1497 | D12: =MAX(0,MIN(D10,D5-D9-D11)) -> 4972.1497 | E12: =MAX(0,MIN(E10,E5-E9-E11)) -> 5008.6736 | F12: =MAX(0,MIN(F10,F5-F9-F11)) -> 5008.6736 | G12: =MAX(0,MIN(G10,G5-G9-G11)) -> 4734.6874 | H12: =MAX(0,MIN(H10,H5-H9-H11)) -> 4141.7452 | I12: =MAX(0,MIN(I10,I5-I9-I11)) -> 4972.1497 | J12: =MAX(0,MIN(J10,J5-J9-J11)) -> 5122.4578 | ... N12: =MAX(0,MIN(N10,N5-N9-N11)) -> 4972.1497 | P12: Limitada pelo consumo restante apos autoconsumo e disponibilidade
B13: Excedente que nao sera aproveitado (kWh) | C13: =C10-C12 -> 1970.0913 | D13: =D10-D12 -> 1818.379 | E13: =E10-E12 -> 478.25388 | F13: =F10-F12 -> 478.25388 | G13: =G10-G12 -> 0 | H13: =H10-H12 -> 0 | I13: =I10-I12 -> 857.53458 | J13: =J10-J12 -> 98.973186 | ... N13: =N10-N12 -> 4144.634 | P13: Credito com prazo de 60 meses. Sobredimensionar e desperdicio
B14: Energia ainda comprada da rede (kWh) | C14: =MAX(C11,C5-C9-C12) -> 600 | D14: =MAX(D11,D5-D9-D12) -> 600 | E14: =MAX(E11,E5-E9-E12) -> 600 | F14: =MAX(F11,F5-F9-F12) -> 600 | G14: =MAX(G11,G5-G9-G12) -> 1196.3748 | H14: =MAX(H11,H5-H9-H12) -> 2043.435 | I14: =MAX(I11,I5-I9-I12) -> 600 | J14: =MAX(J11,J5-J9-J12) -> 600 | ... N14: =MAX(N11,N5-N9-N12) -> 600 | P14: O que continua sendo faturado
B15: Custo da energia comprada (R$) | C15: =C14*C7 -> 612.882 | D15: =D14*D7 -> 612.882 | E15: =E14*E7 -> 612.882 | F15: =F14*F7 -> 612.882 | G15: =G14*G7 -> 1222.0609 | H15: =H14*H7 -> 2087.3075 | I15: =I14*I7 -> 612.882 | J15: =J14*J7 -> 612.882 | ... N15: =N14*N7 -> 612.882
B16: Custo do Fio B sobre a energia compensada (R$) | C16: =C12*ENTRADAS!$C$25 -> 1067.5941 | D16: =D12*ENTRADAS!$C$25 -> 1067.5941 | E16: =E12*ENTRADAS!$C$25 -> 1075.4363 | F16: =F12*ENTRADAS!$C$25 -> 1075.4363 | G16: =G12*ENTRADAS!$C$25 -> 1016.6075 | H16: =H12*ENTRADAS!$C$25 -> 889.294 | I16: =I12*ENTRADAS!$C$25 -> 1067.5941 | J16: =J12*ENTRADAS!$C$25 -> 1099.8675 | ... N16: =N12*ENTRADAS!$C$25 -> 1067.5941 | P16: Lei 14.300: 60% da TUSD Fio B em 2026, 100% a partir de 2029
B17: COSIP / iluminacao publica (R$) | C17: =ENTRADAS!$C$26*12 -> 253.32 | D17: =ENTRADAS!$C$26*12 -> 253.32 | E17: =ENTRADAS!$C$26*12 -> 253.32 | F17: =ENTRADAS!$C$26*12 -> 253.32 | G17: =ENTRADAS!$C$26*12 -> 253.32 | H17: =ENTRADAS!$C$26*12 -> 253.32 | I17: =ENTRADAS!$C$26*12 -> 253.32 | J17: =ENTRADAS!$C$26*12 -> 253.32 | ... N17: =ENTRADAS!$C$26*12 -> 253.32 | P17: R$ 21,11 por mes. A geracao nao afeta
B18: CONTA ANUAL COM SOLAR (R$) | C18: =C15+C16+C17 -> 1933.7961 | D18: =D15+D16+D17 -> 1933.7961 | E18: =E15+E16+E17 -> 1941.6383 | F18: =F15+F16+F17 -> 1941.6383 | G18: =G15+G16+G17 -> 2491.9884 | H18: =H15+H16+H17 -> 3229.9215 | I18: =I15+I16+I17 -> 1933.7961 | J18: =J15+J16+J17 -> 1966.0695 | ... N18: =N15+N16+N17 -> 1933.7961 | P18: O que voce continuara pagando por ano
B19: CONTA MEDIA MENSAL COM SOLAR (R$) | C19: =C18/12 -> 161.14968 | D19: =D18/12 -> 161.14968 | E19: =E18/12 -> 161.8032 | F19: =F18/12 -> 161.8032 | G19: =G18/12 -> 207.6657 | H19: =H18/12 -> 269.16013 | I19: =I18/12 -> 161.14968 | J19: =J18/12 -> 163.83912 | ... N19: =N18/12 -> 161.14968 | P19: A prova de que nao existe conta de R$ 0
B20: Reducao da conta | C20: =IFERROR(1-C18/C8,0) -> 0.76935893 | D20: =IFERROR(1-D18/D8,0) -> 0.76935893 | E20: =IFERROR(1-E18/E8,0) -> 0.7684236 | F20: =IFERROR(1-F18/F8,0) -> 0.7684236 | G20: =IFERROR(1-G18/G8,0) -> 0.70278415 | H20: =IFERROR(1-H18/H8,0) -> 0.61477193 | I20: =IFERROR(1-I18/I8,0) -> 0.76935893 | J20: =IFERROR(1-J18/J8,0) -> 0.76550973 | ... N20: =IFERROR(1-N18/N8,0) -> 0.76935893
B21: Economia bruta anual (R$) | C21: =C8-C18 -> 6450.6435 | D21: =D8-D18 -> 6450.6435 | E21: =E8-E18 -> 6442.8013 | F21: =F8-F18 -> 6442.8013 | G21: =G8-G18 -> 5892.4513 | H21: =H8-H18 -> 5154.5181 | I21: =I8-I18 -> 6450.6435 | J21: =J8-J18 -> 6418.3702 | ... N21: =N8-N18 -> 6450.6435
B22: Manutencao e limpeza (R$/ano) | C22: =ENTRADAS!$C$35 -> 300 | D22: =ENTRADAS!$C$35 -> 300 | E22: =ENTRADAS!$C$35 -> 300 | F22: =ENTRADAS!$C$35 -> 300 | G22: =ENTRADAS!$C$35 -> 300 | H22: =ENTRADAS!$C$35 -> 300 | I22: =ENTRADAS!$C$35 -> 300 | J22: =ENTRADAS!$C$35 -> 300 | ... N22: =ENTRADAS!$C$35 -> 300 | P22: Custo recorrente real
B23: Provisao para troca do inversor (R$/ano) | C23: =ENTRADAS!$C$36 -> 150 | D23: =ENTRADAS!$C$36 -> 150 | E23: =ENTRADAS!$C$36 -> 150 | F23: =ENTRADAS!$C$36 -> 150 | G23: =ENTRADAS!$C$36 -> 150 | H23: =ENTRADAS!$C$36 -> 150 | I23: =ENTRADAS!$C$36 -> 150 | J23: =ENTRADAS!$C$36 -> 150 | ... N23: =ENTRADAS!$C$36 -> 150 | P23: O inversor nao dura os 25 anos do modulo
B24: Reservado | C24: =0 -> 0 | D24: =0 -> 0 | E24: =0 -> 0 | F24: =0 -> 0 | G24: =0 -> 0 | H24: =0 -> 0 | I24: =0 -> 0 | J24: =0 -> 0 | ... N24: =0 -> 0 | P24: Degradacao ja tratada no fator de geracao da aba PROJECAO
B25: Subtotal de custos recorrentes (R$) | C25: =C22+C23 -> 450 | D25: =D22+D23 -> 450 | E25: =E22+E23 -> 450 | F25: =F22+F23 -> 450 | G25: =G22+G23 -> 450 | H25: =H22+H23 -> 450 | I25: =I22+I23 -> 450 | J25: =J22+J23 -> 450 | ... N25: =N22+N23 -> 450
B26: ECONOMIA LIQUIDA NO ANO 1 (R$) | C26: =C21-C25 -> 6000.6435 | D26: =D21-D25 -> 6000.6435 | E26: =E21-E25 -> 5992.8013 | F26: =F21-F25 -> 5992.8013 | G26: =G21-G25 -> 5442.4513 | H26: =H21-H25 -> 4704.5181 | I26: =I21-I25 -> 6000.6435 | J26: =J21-J25 -> 5968.3702 | ... N26: =N21-N25 -> 6000.6435 | P26: Base do payback e da projecao de 20 anos
B28: SIMULACAO SEM CARRO x COM CARRO (impacto isolado do BYD)
B29: Consumo anual SEM o BYD (kWh) | C29: =BYD!$F$33*12 -> 4221.9251 | P29: Media real da conta x 12
B30: Consumo anual COM o BYD (kWh) | C30: =BYD!$F$34*12 -> 6921.9251 | P30: Cenario 2
B31: Acrescimo de consumo causado pelo BYD (kWh/ano) | C31: =C30-C29 -> 2700 | P31: Inclui as perdas de carregamento
B32: Acrescimo percentual sobre o consumo atual | C32: =IFERROR(C30/C29-1,0) -> 0.63951869 | P32: Por isso a media da conta nao serve de base
B33: Conta anual SEM solar e SEM o BYD (R$) | C33: =C29*ENTRADAS!C18+ENTRADAS!C26*12 -> 4565.8898 | P33: Sua situacao de hoje
B34: Conta anual SEM solar e COM o BYD (R$) | C34: =C30*ENTRADAS!C18+ENTRADAS!C26*12 -> 7323.8588 | P34: O carro sozinho encarece a conta neste valor
B35: Custo anual so do BYD sem energia solar (R$) | C35: =C31*ENTRADAS!C18 -> 2757.969 | P35: Na tarifa cheia
B36: Custo anual so do BYD com energia solar (R$) | C36: =C31*ENTRADAS!C25 -> 579.72996 | P36: Compensado: paga-se apenas o Fio B
B37: ECONOMIA ANUAL SO NO CARREGAMENTO DO BYD (R$) | C37: =C35-C36 -> 2178.239 | P37: O melhor retorno marginal do projeto
B38: Numero de placas de 615 W dedicadas ao BYD | C38: =IFERROR(ROUNDUP(C31/GERACAO!I17*1000/615,0),0) -> 4 | P38: Placas que existem por causa do carro

Sheet PROJECAO
A1: PROJECAO DE 20 ANOS, ECONOMIA ACUMULADA E PAYBACK
A2: Economia do ano 1 corrigida por inflacao energetica e degradacao, menos O&M. 'Fluxo' = acumulado menos o investimento; fica positivo no ano do payback.
